Workbook

Sheet Info
C5: Select your language in the drop-down in the green area / Seleccione su idioma en el desplegable del área verde | H5: English / Inglés
C13: =IF(D34=1,"GENERAL INFORMATION","INFORMACIÓN GENERAL") -> GENERAL INFORMATION
C16: =IF(D34=1,"This Excel file was created to register your measurements of 20 subjects and to calculate your Technical Error of Measurement after that.","Este archivo de Excel ha sido creado para registrar sus mediciones de los 20 sujetos y para calcular su Error Técnico de Medida.") -> This Excel file was created to register your measurements of 20 subjects and to calculate your Technical Error of Measurement after that.
C17: =IF(D34=1,"You must take measurements of twenty (20) individuals, registering two times for each varaible, or three times if it is indicated in the corresponding cell.","Debe tomar medidas de veinte (20) individuos, registrando dos veces cada varaible, o tres veces si así se indica en la celda correspondiente.") -> You must take measurements of twenty (20) individuals, registering two times for each varaible, or three times if it is indicated in the corresponding cell.
B18: 1 | M18: 12 | N18: 13 | O18: 14 | P18: 15 | Q18: 16 | R18: 17 | S18: 18 | T18: 19 | U18: 20
C19: =IF(D34=1,"You must complete the grey cells of the tabs ''1.'' to ''20.''","Debe completar las celdas coloreadas en gris de las pestañas ''1.'' a ''20.''.") -> You must complete the grey cells of the tabs ''1.'' to ''20.''
C20: =IF(D34=1,"You must not change the name of any tab.","No cambie el nombre de las pestañas del excel.") -> You must not change the name of any tab.
C22: =IF(D34=1,"If you want to print information out for the subject, it is necessary to save that tab as a pdf. The file is ready to automatically take the individual's report.","Si desea entregar un informe a la persona ecaluada puede guardar como PDF la pestaña en la que ha incluido las medidas de dicho sujeto. El archivo está preparado para sacar automáticamente su informe individual.") -> If you want to print information out for the subject, it is necessary to save that tab as a pdf. The file is ready to automatically take the individual's report.
C25: =IF(D34=1,"While typing in data, make sure to save the spreadsheet frequently in order to avoid accidents which could result in loss of typed data.","Mientras que introduce los datos, asegúrese de grabar con frecuencia la hoja para la toma de datos de manera que evite accidentes que podrian producir la perdida de datos.") -> While typing in data, make sure to save the spreadsheet frequently in order to avoid accidents which could result in loss of typed data.
C27: =IF(D34=1,"When you finish entering the data of the 20 subjects, send this sheet to the instructor responsible for your course.","Cuando termine de introducir los datos de los 20 sujetos, envíe esta hoja al instructor responsable de su curso.") -> When you finish entering the data of the 20 subjects, send this sheet to the instructor responsible for your course.
C29: =IF(D34=1,"The sheet named ''Graphs'' shows graphs comparing the measured and target %TEM.","Las hojas llamadas ''gráficos'' muestran gráficos que comparan los errores ETM medidos y el porcentaje objetivo.") -> The sheet named ''Graphs'' shows graphs comparing the measured and target %TEM.
C34: English / Inglés | D34: =IF(H5="English / Inglés",1,0) -> 1
C35: Spanish / Español

Sheet TEM info
C2: =IF(Info!D34=1,"SPREADSHEET FOR MEASUREMENT ERROR", "HOJA DE CALCULO PARA EL ERROR DE MEDIDA") -> SPREADSHEET FOR MEASUREMENT ERROR
C5: =IF(Info!D34=1,"This spreadsheet calculates the Technical Error of Measurement (TEM) and the Intraclass Correlation Coefficient (ICC) from a one-way ANOVA.","Esta hoja de cálculo permite el calculo del Error Tecnico de Medida (ETM) y el coeficiente de Correlación Intraclase (ICC) por el metodo ANOVA.") -> This spreadsheet calculates the Technical Error of Measurement (TEM) and the Intraclass Correlation Coefficient (ICC) from a one-way ANOVA.
C7: =IF(Info!D34=1,"[For additional information on the statistical calculations, refer to Norton & Olds (1996) or other statistics textbooks.]","Para información adicional sobre los calculos estadísticos, consulte Norton & Olds (1996) u otros textos de estadística.") -> [For additional information on the statistical calculations, refer to Norton & Olds (1996) or other statistics textbooks.]
C10: =IF(Info!D34=1,"The calculations are based on two (or the closest two of three) measures on twenty (20) subjects.", "Los cálculos se refieren a dos medidas (2), o las dos más cercanas si son tres medidas, sobre veinte (20) sujetos.") -> The calculations are based on two (or the closest two of three) measures on twenty (20) subjects.
C11: =IF(Info!D34=1, "The intra-tester target %TEMs for obtaining ISAK accreditation are:", "El porcentaje de Error del ETM para el inter- e intra-evaulador para obtener la acreditacion ISAK se muestran en la tabla inferior.") -> The intra-tester target %TEMs for obtaining ISAK accreditation are:
E13: =IF(Info!D34=1, "Level 1", "Nivel 1") -> Level 1 | G13: =IF(Info!D34=1, "Level 2, 3 and 4","Nivel 2, 3 y 4") -> Level 2, 3 and 4
E14: =IF(Info!D34=1, "Post-course","Tras el curso") -> Post-course | F14: =IF(Info!D34=1, "Post-profiles","Post-perfiles") -> Post-profiles | G14: =IF(Info!D34=1, "Post-course","Tras el curso") -> Post-course | H14: =IF(Info!D34=1, "Post-profiles","Post-perfiles") -> Post-profiles
C15: inter | D15: =IF(Info!D34=1, "Skinfolds","Pliegues") -> Skinfolds | E15: 12.5 | F15: 10 | G15: 10 | H15: 7.5
D16: =IF(Info!D34=1, "Other measurs","Otras medidas") -> Other measurs | E16: 2.5 | F16: 2 | G16: 2 | H16: 1.5
C17: intra | D17: =IF(Info!D34=1, "Skinfolds","Pliegues") -> Skinfolds | E17: 10 | F17: 7.5 | G17: 7.5 | H17: 5
D18: =IF(Info!D34=1, "Other measurs","Otras medidas") -> Other measurs | E18: 2 | F18: 1.5 | G18: 1.5 | H18: 1
E20: =IF(Info!D34=1, "Number of subjects:","Numero de sujetos:") -> Number of subjects: | F20: 20
E21: =IF(Info!D34=1, "Measuments per subject:","Medida por sujeto:") -> Measuments per subject: | F21: 2
B31: 1 | C31: 2 | D31: 3 | E31: 4 | F31: 5 | G31: 6 | H31: 7 | I31: 8 | J31: 9 | K31: 10 | L31: 11 | M31: 12 | N31: 13 | O31: 14 | P31: 15 | Q31: 16 | R31: 17 | S31: 18 | T31: 19 | U31: 20

Sheet 1
B2: =IF(Info!D34,"ISAK RESTRICTED PROFORMA","PROFORMA PERFIL RESTRINGIDO ISAK") -> ISAK RESTRICTED PROFORMA | R2: =IF(Info!D34,"ISAK PROFORMA PRINTOUT","INFORME PROFORMA ISAK") -> ISAK PROFORMA PRINTOUT
B4: =IF(Info!D34,"Name","Nombre") -> Name | G4: STEPHAN | R4: =+B4 -> Name | U4: =+G4 -> STEPHAN
B5: =IF(Info!D34,"Surname","Apellidos") -> Surname | G5: BREADT | R5: =+B5 -> Surname | U5: =+G5 -> BREADT
B6: =IF(Info!D34,"Country","País") -> Country | R6: =+B6 -> Country | U6: =+G6 -> 0
B7: =IF(Info!D34,"Ethnicity (Asian=1; African-American=2; Caucasian=3)","Raza (asiático=1; afro-americano=2; caucásico=3)") -> Ethnicity (Asian=1; African-American=2; Caucasian=3) | R7: =+B7 -> Ethnicity (Asian=1; African-American=2; Caucasian=3) | U7: =+G7 -> 0
B8: =IF(Info!D34,"Sex (male=1, female=2)","Sexo (hombre=1, mujer=2)") -> Sex (male=1, female=2) | G8: 1 | R8: =+B8 -> Sex (male=1, female=2) | U8: =+G8 -> 1
B9: =IF(Info!D34,"Sport","Deporte") -> Sport | R9: =+B9 -> Sport | U9: =+G9 -> 0
B10: =IF(Info!D34,"Date of Measurement","Fecha de la valoración") -> Date of Measurement | G10: 46086 | R10: =+B10 -> Date of Measurement | U10: =+G10 -> 46086
B11: =IF(Info!D34,"Date of Birth","Fecha de nacimiento") -> Date of Birth | K11: =IF(Info!D34,"3rd measure?","¿3ª medida?") -> 3rd measure? | N11: =IF(Info!D34,"Mean or Median","Media o Mediana") -> Mean or Median | R11: =+B11 -> Date of Birth | U11: =+G11 -> 0
B12: =IF(Info!D34,"Measure","Medida") -> Measure | H12: 2 | I12: 3 | U12: =IF(Info!D34,"Value", "Valor") -> Value | W12: =IF(Info!D34,"Phantom Z-value","Valor Z del Phantom") -> Phantom Z-value
B13: =IF(Info!D34,"Mass","Masa corporal") -> Mass | G13: 100.5 | K13: =+(H13-G13)/(AVERAGE(G13:H13)) -> -1 | L13: =IF(ABS(K13)>1%,"Yes","No") -> Yes | N13: =IF(I13=0,AVERAGE(G13,H13),MEDIAN(G13,H13,I13)) -> 100.5 | R13: =+B13 -> Mass | U13: =+N13 -> 100.5 | V13: kg | W13: =1/8.6*(+U13*((170.18/U$14)^3)-64.58) -> 1.7363956
B14: =IF(Info!D34,"Stature","Talla") -> Stature | G14: 184 | K14: =+(H14-G14)/(AVERAGE(G14:H14)) -> -1 | L14: =IF(ABS(K14)>1%,"Yes","No") -> Yes | N14: =IF(I14=0,AVERAGE(G14,H14),MEDIAN(G14,H14,I14)) -> 184 | R14: =+B14 -> Stature | U14: =+N14 -> 184 | V14: cm
B15: =IF(Info!D34,"Sitting height","Talla sentado") -> Sitting height | K15: =+(H15-G15)/(AVERAGE(G15:H15)) -> #DIV/0! | L15: =IF(ABS(K15)>1%,"Yes","No") -> #DIV/0! | N15: =IF(I15=0,AVERAGE(G15,H15),MEDIAN(G15,H15,I15)) -> #DIV/0! | R15: =+B15 -> Sitting height | U15: =+N15 -> #DIV/0! | V15: cm | W15: =1/4.5*(+U15*((170.18/U$14)^1)-89.92) -> #DIV/0!
B16: =IF(Info!D34,"Arm Span","Envergadura de brazos") -> Arm Span | K16: =+(H16-G16)/(AVERAGE(G16:H16)) -> #DIV/0! | L16: =IF(ABS(K16)>1%,"Yes","No") -> #DIV/0! | N16: =IF(I16=0,AVERAGE(G16,H16),MEDIAN(G16,H16,I16)) -> #DIV/0! | R16: =+B16 -> Arm Span | U16: =+N16 -> #DIV/0! | V16: cm | W16: =1/7.41*(+U16*((170.18/U$14)^1)-172.35) -> #DIV/0!
B17: =IF(Info!D34,"Triceps sf","PL Tríceps") -> Triceps sf | G17: 12 | K17: =+(H17-G17)/(AVERAGE(G17:H17)) -> -1 | L17: =IF(ABS(K17)>5%,"Yes","No") -> Yes | N17: =IF(I17=0,AVERAGE(G17,H17),MEDIAN(G17,H17,I17)) -> 12 | R17: =+B17 -> Triceps sf | U17: =+N17 -> 12 | V17: mm | W17: =1/4.47*(+U17*((170.18/U$14)^1)-15.4) -> -0.96226048
B18: =IF(Info!D34,"Subscapular sf","PL Subescapular") -> Subscapular sf | G18: 20 | K18: =+(H18-G18)/(AVERAGE(G18:H18)) -> -1 | L18: =IF(ABS(K18)>5%,"Yes","No") -> Yes | N18: =IF(I18=0,AVERAGE(G18,H18),MEDIAN(G18,H18,I18)) -> 20 | R18: =+B18 -> Subscapular sf | U18: =+N18 -> 20 | V18: mm | W18: =1/5.07*(+U18*((170.18/U$14)^1)-17.2) -> 0.25598148
B19: =IF(Info!D34,"Biceps sf","PL Bíceps") -> Biceps sf | G19: 7 | K19: =+(H19-G19)/(AVERAGE(G19:H19)) -> -1 | L19: =IF(ABS(K19)>5%,"Yes","No") -> Yes | N19: =IF(I19=0,AVERAGE(G19,H19),MEDIAN(G19,H19,I19)) -> 7 | R19: =+B19 -> Biceps sf | U19: =+N19 -> 7 | V19: mm | W19: =1/2*(+U19*((170.18/U$14)^1)-8) -> -0.76288043
B20: =IF(Info!D34,"Iliac crest sf","PL Cresta Iliaca") -> Iliac crest sf | G20: 43 | K20: =+(H20-G20)/(AVERAGE(G20:H20)) -> -1 | L20: =IF(ABS(K20)>5%,"Yes","No") -> Yes | N20: =IF(I20=0,AVERAGE(G20,H20),MEDIAN(G20,H20,I20)) -> 43 | R20: =+B20 -> Iliac crest sf | U20: =+N20 -> 43 | V20: mm | W20: =1/6.8*(+U20*((170.18/U$14)^1)-22.4) -> 2.5544597
B21: =IF(Info!D34,"Supraspinale sf","PL Supraespinal") -> Supraspinale sf | G21: 20 | K21: =+(H21-G21)/(AVERAGE(G21:H21)) -> -1 | L21: =IF(ABS(K21)>5%,"Yes","No") -> Yes | N21: =IF(I21=0,AVERAGE(G21,H21),MEDIAN(G21,H21,I21)) -> 20 | R21: =+B21 -> Supraspinale sf | U21: =+N21 -> 20 | V21: mm | W21: =1/4.47*(+U21*((170.18/U$14)^1)-15.4) -> 0.69302597
B22: =IF(Info!D34,"Abdominal sf","PL Abdominal") -> Abdominal sf | G22: 37 | K22: =+(H22-G22)/(AVERAGE(G22:H22)) -> -1 | L22: =IF(ABS(K22)>5%,"Yes","No") -> Yes | N22: =IF(I22=0,AVERAGE(G22,H22),MEDIAN(G22,H22,I22)) -> 37 | R22: =+B22 -> Abdominal sf | U22: =+N22 -> 37 | V22: mm | W22: =1/7.78*(+U22*((170.18/U$14)^1)-25.4) -> 1.1338018
B23: =IF(Info!D34,"Thigh sf","PL Muslo") -> Thigh sf | G23: 27 | K23: =+(H23-G23)/(AVERAGE(G23:H23)) -> -1 | L23: =IF(ABS(K23)>5%,"Yes","No") -> Yes | N23: =IF(I23=0,AVERAGE(G23,H23),MEDIAN(G23,H23,I23)) -> 27 | R23: =+B23 -> Thigh sf | U23: =+N23 -> 27 | V23: mm | W23: =1/8.33*(+U23*((170.18/U$14)^1)-27) -> -0.24344955
B24: =IF(Info!D34,"Calf sf","PL Pierna") -> Calf sf | G24: 8 | K24: =+(H24-G24)/(AVERAGE(G24:H24)) -> -1 | L24: =IF(ABS(K24)>5%,"Yes","No") -> Yes | N24: =IF(I24=0,AVERAGE(G24,H24),MEDIAN(G24,H24,I24)) -> 8 | R24: =+B24 -> Calf sf | U24: =+N24 -> 8 | V24: mm | W24: =1/4.67*(+U24*((170.18/U$14)^1)-16) -> -1.841728
B25: =IF(Info!D34,"Arm girth relaxed","PR Brazo relajado") -> Arm girth relaxed | G25: 37 | K25: =+(H25-G25)/(AVERAGE(G25:H25)) -> -1 | L25: =IF(ABS(K25)>1%,"Yes","No") -> Yes | N25: =IF(I25=0,AVERAGE(G25,H25),MEDIAN(G25,H25,I25)) -> 37 | R25: =+B25 -> Arm girth relaxed | U25: =+N25 -> 37 | V25: cm | W25: =1/2.33*(+U25*((170.18/U$14)^1)-26.89) -> 3.1463426
B26: =IF(Info!D34,"Corrected arm girth","PR Brazo corregido") -> Corrected arm girth | R26: =+B26 -> Corrected arm girth | U26: =+U25-(PI()*U17/10) -> 33.230089 | V26: cm | W26: =1/1.91*(+U26*((170.18/U$14)^1)-22.05) -> 4.5467121
B27: =IF(Info!D34,"Arm girth flexed and tensed","PR Brazo flexionado y contraído") -> Arm girth flexed and tensed | G27: 40 | K27: =+(H27-G27)/(AVERAGE(G27:H27)) -> -1 | L27: =IF(ABS(K27)>1%,"Yes","No") -> Yes | N27: =IF(I27=0,AVERAGE(G27,H27),MEDIAN(G27,H27,I27)) -> 40 | R27: =+B27 -> Arm girth flexed and tensed | U27: =+N27 -> 40 | V27: cm | W27: =1/2.37*(+U27*((170.18/U$14)^1)-29.41) -> 3.2006971
B28: =IF(Info!D34,"Waist girth","PR Cintura") -> Waist girth | G28: 101 | K28: =+(H28-G28)/(AVERAGE(G28:H28)) -> -1 | L28: =IF(ABS(K28)>1%,"Yes","No") -> Yes | N28: =IF(I28=0,AVERAGE(G28,H28),MEDIAN(G28,H28,I28)) -> 101 | R28: =+B28 -> Waist girth | U28: =+N28 -> 101 | V28: cm | W28: =1/4.45*(+U28*((170.18/U$14)^1)-71.91) -> 4.8323644
B29: =IF(Info!D34,"Hips girth","PR Caderas") -> Hips girth | G29: 115 | K29: =+(H29-G29)/(AVERAGE(G29:H29)) -> -1 | L29: =IF(ABS(K29)>1%,"Yes","No") -> Yes | N29: =IF(I29=0,AVERAGE(G29,H29),MEDIAN(G29,H29,I29)) -> 115 | R29: =+B29 -> Hips girth | U29: =+N29 -> 115 | V29: cm | W29: =1/5.58*(+U29*((170.18/U$14)^1)-94.67) -> 2.0954301
B30: =IF(Info!D34,"Thigh middle girth","PR Muslo medio") -> Thigh middle girth | G30: 60.5 | K30: =+(H30-G30)/(AVERAGE(G30:H30)) -> -1 | L30: =IF(ABS(K30)>1%,"Yes","No") -> Yes | N30: =IF(I30=0,AVERAGE(G30,H30),MEDIAN(G30,H30,I30)) -> 60.5 | R30: =+B30 -> Thigh middle girth | U30: =+N30 -> 60.5 | V30: cm | W30: =1/4.56*(+U30*((170.18/U$14)^1)-53.2) -> 0.60436928
B31: =IF(Info!D34,"Corrected thigh girth","PR Muslo corregido") -> Corrected thigh girth | R31: =+B31 -> Corrected thigh girth | U31: =+U30-(PI()*U23/10) -> 52.0177 | V31: cm | W31: =1/3.59*(+U31*((170.18/U$14)^1)-47.34) -> 0.21468475
B32: =IF(Info!D34,"Calf girth","PR Pierna") -> Calf girth | G32: 41.5 | K32: =+(H32-G32)/(AVERAGE(G32:H32)) -> -1 | L32: =IF(ABS(K32)>1%,"Yes","No") -> Yes | N32: =IF(I32=0,AVERAGE(G32,H32),MEDIAN(G32,H32,I32)) -> 41.5 | R32: =+B32 -> Calf girth | U32: =+N32 -> 41.5 | V32: cm | W32: =1/2.3*(+U32*((170.18/U$14)^1)-35.25) -> 1.3621692
B33: =IF(Info!D34,"Corrected calf girth","PR Pierna corregido") -> Corrected calf girth | R33: =+B33 -> Corrected calf girth | U33: =+U32-(PI()*U24/10) -> 38.986726 | V33: cm | W33: =1/1.97*(+U33*((170.18/U$14)^1)-30.22) -> 2.9636973
B34: =IF(Info!D34,"Humerus breadth","D Húmero") -> Humerus breadth | G34: 7.2 | K34: =+(H34-G34)/(AVERAGE(G34:H34)) -> -1 | L34: =IF(ABS(K34)>1%,"Yes","No") -> Yes | N34: =IF(I34=0,AVERAGE(G34,H34),MEDIAN(G34,H34,I34)) -> 7.2 | R34: =+B34 -> Humerus breadth | U34: =+N34 -> 7.2 | V34: cm | W34: =1/0.35*(+U34*((170.18/U$14)^1)-6.48) -> 0.51204969
B35: =IF(Info!D34,"Bi-styloid breadth","D Biestiloideo") -> Bi-styloid breadth | G35: 5.8 | K35: =+(H35-G35)/(AVERAGE(G35:H35)) -> -1 | L35: =IF(ABS(K35)>1%,"Yes","No") -> Yes | N35: =IF(I35=0,AVERAGE(G35,H35),MEDIAN(G35,H35,I35)) -> 5.8 | R35: =+B35 -> Bi-styloid breadth | U35: =+N35 -> 5.8 | V35: cm | W35: =1/0.28*(+U35*((170.18/U$14)^1)-5.21) -> 0.55131988
B36: =IF(Info!D34,"Femur breadth","D Fémur") -> Femur breadth | G36: 10.8 | K36: =+(H36-G36)/(AVERAGE(G36:H36)) -> -1 | L36: =IF(ABS(K36)>1%,"Yes","No") -> Yes | N36: =IF(I36=0,AVERAGE(G36,H36),MEDIAN(G36,H36,I36)) -> 10.8 | R36: =+B36 -> Femur breadth | U36: =+N36 -> 10.8 | V36: cm | W36: =1/0.48*(+U36*((170.18/U$14)^1)-9.52) -> 0.97672101
D39: 1ª Vs 2ª | E39: 1ªVs 3ª | F39: 2ª Vs 3ª | G39: =IF(Info!D34,"3rd measure taken?","¿3ª medida tomada?") -> 3rd measure taken? | H39: =IF(Info!D34,"3rd measure requested?","¿3ª medida solicitada?") -> 3rd measure requested? | I39: =IF(Info!D34,"He/she has not done 1st measure","No se ha realizado la 1ª medición") -> He/she has not done 1st measure | J39: =IF(Info!E34,"He/she has not done 2nd measure","No se ha realizado la 2ª medición") -> No se ha realizado la 2ª medición
B40: =B13 -> Mass | D40: =IF(G13=H13,1,0) -> 0 | E40: =IF(G13=I13,1,0) -> 0 | F40: =IF(H13=I13,1,0) -> 1 | G40: =IF(I13="",0,1) -> 0 | H40: =IF(L13="Yes",1,0) -> 1 | I40: =COUNTIF(G13,"") -> 0 | J40: =COUNTIF(H13,"") -> 1 | S40: ='3'!S40 -> Somatotype | T40: =IF(Info!D34,"Endomorphy","Endomorfia") -> Endomorphy | U40: =-0.7182+0.1451*((U17+U18+U21)*(170.18/U14))-0.00068*(((U17+U18+U21)*(170.18/U14))^2)+0.0000014*(((U17+U18+U21)*(170.18/U14))^3) -> 4.8431484
B41: =B14 -> Stature | D41: =IF(G14=H14,1,0) -> 0 | E41: =IF(G14=I14,1,0) -> 0 | F41: =IF(H14=I14,1,0) -> 1 | G41: =IF(I14="",0,1) -> 0 | H41: =IF(L14="Yes",1,0) -> 1 | I41: =COUNTIF(G14,"") -> 0 | J41: =COUNTIF(H14,"") -> 1 | S41: ='3'!S41 -> (Heath-Carter) | T41: =IF(Info!D34,"Mesomorphy","Mesomorfia") -> Mesomorphy | U41: =(0.858*U34)+(0.601*U36)+(0.188*(U27-(U17/10)))+(0.161*(U32-(U24/10)))-(0.131*U14)+4.5 -> 6.9115
B42: =B15 -> Sitting height | D42: =IF(G15=H15,1,0) -> 1 | E42: =IF(G15=I15,1,0) -> 1 | F42: =IF(H15=I15,1,0) -> 1 | G42: =IF(I15="",0,1) -> 0 | H42: =IF(L15="Yes",1,0) -> #DIV/0! | I42: =COUNTIF(G15,"") -> 1 | J42: =COUNTIF(H15,"") -> 1 | T42: =IF(Info!D34,"Ectomorphy","Ectomorfia") -> Ectomorphy | U42: =IF(V42>40.75,((0.732*V42)-28.58),IF(V42>38.28,((0.463*V42)-17.63),0.1)) -> 0.69357148 | V42: =U14/(U13^(1/3)) -> 39.575748
B43: =B16 -> Arm Span | D43: =IF(G16=H16,1,0) -> 1 | E43: =IF(G16=I16,1,0) -> 1 | F43: =IF(H16=I16,1,0) -> 1 | G43: =IF(I16="",0,1) -> 0 | H43: =IF(L16="Yes",1,0) -> #DIV/0! | I43: =COUNTIF(G16,"") -> 1 | J43: =COUNTIF(H16,"") -> 1
B44: =B17 -> Triceps sf | D44: =IF(G17=H17,1,0) -> 0 | E44: =IF(G17=I17,1,0) -> 0 | F44: =IF(H17=I17,1,0) -> 1 | G44: =IF(I17="",0,1) -> 0 | H44: =IF(L17="Yes",1,0) -> 1 | I44: =COUNTIF(G17,"") -> 0 | J44: =COUNTIF(H17,"") -> 1 | S44: ='3'!S44 -> Body Mass Index (MBI) | U44: =+U13/(U14/100)^2 -> 29.684546 | V44: ='3'!V44 -> kg/m2
...

Sheet 2
B2: =IF(Info!D34,"ISAK RESTRICTED PROFORMA","PROFORMA PERFIL RESTRINGIDO ISAK") -> ISAK RESTRICTED PROFORMA | R2: =IF(Info!D34,"ISAK PROFORMA PRINTOUT","INFORME PROFORMA ISAK") -> ISAK PROFORMA PRINTOUT
B4: =IF(Info!D34,"Name","Nombre") -> Name | R4: =+B4 -> Name | U4: =+G4 -> 0
B5: =IF(Info!D34,"Surname","Apellidos") -> Surname | R5: =+B5 -> Surname | U5: =+G5 -> 0
B6: =IF(Info!D34,"Country","País") -> Country | R6: =+B6 -> Country | U6: =+G6 -> 0
B7: =IF(Info!D34,"Ethnicity (Asian=1; African-American=2; Caucasian=3)","Raza (asiático=1; afro-americano=2; caucásico=3)") -> Ethnicity (Asian=1; African-American=2; Caucasian=3) | G7: 3 | R7: =+B7 -> Ethnicity (Asian=1; African-American=2; Caucasian=3) | U7: =+G7 -> 3
B8: =IF(Info!D34,"Sex (male=1, female=2)","Sexo (hombre=1, mujer=2)") -> Sex (male=1, female=2) | G8: 1 | R8: =+B8 -> Sex (male=1, female=2) | U8: =+G8 -> 1
B9: =IF(Info!D34,"Sport","Deporte") -> Sport | R9: =+B9 -> Sport | U9: =+G9 -> 0
B10: =IF(Info!D34,"Date of Measurement","Fecha de la valoración") -> Date of Measurement | G10: 46175 | R10: =+B10 -> Date of Measurement | U10: =+G10 -> 46175
B11: =IF(Info!D34,"Date of Birth","Fecha de nacimiento") -> Date of Birth | K11: =IF(Info!D34,"3rd measure?","¿3ª medida?") -> 3rd measure? | N11: =IF(Info!D34,"Mean or Median","Media o Mediana") -> Mean or Median | R11: =+B11 -> Date of Birth | U11: =+G11 -> 0
B12: =IF(Info!D34,"Measure","Medida") -> Measure | G12: 1 | H12: 2 | I12: 3 | U12: =IF(Info!D34,"Value", "Valor") -> Value | W12: =IF(Info!D34,"Phantom Z-value","Valor Z del Phantom") -> Phantom Z-value
B13: =IF(Info!D34,"Mass","Masa corporal") -> Mass | G13: 97.5 | K13: =+(H13-G13)/(AVERAGE(G13:H13)) -> -1 | L13: =IF(ABS(K13)>1%,"Yes","No") -> Yes | N13: =IF(I13=0,AVERAGE(G13,H13),MEDIAN(G13,H13,I13)) -> 97.5 | R13: =+B13 -> Mass | U13: =+N13 -> 97.5 | V13: kg | W13: =1/8.6*(+U13*((170.18/U$14)^3)-64.58) -> 1.4604046
B14: =IF(Info!D34,"Stature","Talla") -> Stature | G14: 184 | K14: =+(H14-G14)/(AVERAGE(G14:H14)) -> -1 | L14: =IF(ABS(K14)>1%,"Yes","No") -> Yes | N14: =IF(I14=0,AVERAGE(G14,H14),MEDIAN(G14,H14,I14)) -> 184 | R14: =+B14 -> Stature | U14: =+N14 -> 184 | V14: cm
B15: =IF(Info!D34,"Sitting height","Talla sentado") -> Sitting height | K15: =+(H15-G15)/(AVERAGE(G15:H15)) -> #DIV/0! | L15: =IF(ABS(K15)>1%,"Yes","No") -> #DIV/0! | N15: =IF(I15=0,AVERAGE(G15,H15),MEDIAN(G15,H15,I15)) -> #DIV/0! | R15: =+B15 -> Sitting height | U15: =+N15 -> #DIV/0! | V15: cm | W15: =1/4.5*(+U15*((170.18/U$14)^1)-89.92) -> #DIV/0!
B16: =IF(Info!D34,"Arm Span","Envergadura de brazos") -> Arm Span | K16: =+(H16-G16)/(AVERAGE(G16:H16)) -> #DIV/0! | L16: =IF(ABS(K16)>1%,"Yes","No") -> #DIV/0! | N16: =IF(I16=0,AVERAGE(G16,H16),MEDIAN(G16,H16,I16)) -> #DIV/0! | R16: =+B16 -> Arm Span | U16: =+N16 -> #DIV/0! | V16: cm | W16: =1/7.41*(+U16*((170.18/U$14)^1)-172.35) -> #DIV/0!
B17: =IF(Info!D34,"Triceps sf","PL Tríceps") -> Triceps sf | G17: 12 | K17: =+(H17-G17)/(AVERAGE(G17:H17)) -> -1 | L17: =IF(ABS(K17)>5%,"Yes","No") -> Yes | N17: =IF(I17=0,AVERAGE(G17,H17),MEDIAN(G17,H17,I17)) -> 12 | R17: =+B17 -> Triceps sf | U17: =+N17 -> 12 | V17: mm | W17: =1/4.47*(+U17*((170.18/U$14)^1)-15.4) -> -0.96226048
B18: =IF(Info!D34,"Subscapular sf","PL Subescapular") -> Subscapular sf | G18: 18 | K18: =+(H18-G18)/(AVERAGE(G18:H18)) -> -1 | L18: =IF(ABS(K18)>5%,"Yes","No") -> Yes | N18: =IF(I18=0,AVERAGE(G18,H18),MEDIAN(G18,H18,I18)) -> 18 | R18: =+B18 -> Subscapular sf | U18: =+N18 -> 18 | V18: mm | W18: =1/5.07*(+U18*((170.18/U$14)^1)-17.2) -> -0.10886716
B19: =IF(Info!D34,"Biceps sf","PL Bíceps") -> Biceps sf | G19: 5 | K19: =+(H19-G19)/(AVERAGE(G19:H19)) -> -1 | L19: =IF(ABS(K19)>5%,"Yes","No") -> Yes | N19: =IF(I19=0,AVERAGE(G19,H19),MEDIAN(G19,H19,I19)) -> 5 | R19: =+B19 -> Biceps sf | U19: =+N19 -> 5 | V19: mm | W19: =1/2*(+U19*((170.18/U$14)^1)-8) -> -1.6877717
B20: =IF(Info!D34,"Iliac crest sf","PL Cresta Iliaca") -> Iliac crest sf | G20: 35 | K20: =+(H20-G20)/(AVERAGE(G20:H20)) -> -1 | L20: =IF(ABS(K20)>5%,"Yes","No") -> Yes | N20: =IF(I20=0,AVERAGE(G20,H20),MEDIAN(G20,H20,I20)) -> 35 | R20: =+B20 -> Iliac crest sf | U20: =+N20 -> 35 | V20: mm | W20: =1/6.8*(+U20*((170.18/U$14)^1)-22.4) -> 1.4663523
B21: =IF(Info!D34,"Supraspinale sf","PL Supraespinal") -> Supraspinale sf | G21: 17 | K21: =+(H21-G21)/(AVERAGE(G21:H21)) -> -1 | L21: =IF(ABS(K21)>5%,"Yes","No") -> Yes | N21: =IF(I21=0,AVERAGE(G21,H21),MEDIAN(G21,H21,I21)) -> 17 | R21: =+B21 -> Supraspinale sf | U21: =+N21 -> 17 | V21: mm | W21: =1/4.47*(+U21*((170.18/U$14)^1)-15.4) -> 0.072293551
B22: =IF(Info!D34,"Abdominal sf","PL Abdominal") -> Abdominal sf | G22: 34 | K22: =+(H22-G22)/(AVERAGE(G22:H22)) -> -1 | L22: =IF(ABS(K22)>5%,"Yes","No") -> Yes | N22: =IF(I22=0,AVERAGE(G22,H22),MEDIAN(G22,H22,I22)) -> 34 | R22: =+B22 -> Abdominal sf | U22: =+N22 -> 34 | V22: mm | W22: =1/7.78*(+U22*((170.18/U$14)^1)-25.4) -> 0.77715994
B23: =IF(Info!D34,"Thigh sf","PL Muslo") -> Thigh sf | G23: 22 | K23: =+(H23-G23)/(AVERAGE(G23:H23)) -> -1 | L23: =IF(ABS(K23)>5%,"Yes","No") -> Yes | N23: =IF(I23=0,AVERAGE(G23,H23),MEDIAN(G23,H23,I23)) -> 22 | R23: =+B23 -> Thigh sf | U23: =+N23 -> 22 | V23: mm | W23: =1/8.33*(+U23*((170.18/U$14)^1)-27) -> -0.7986064
B24: =IF(Info!D34,"Calf sf","PL Pierna") -> Calf sf | G24: 7 | K24: =+(H24-G24)/(AVERAGE(G24:H24)) -> -1 | L24: =IF(ABS(K24)>5%,"Yes","No") -> Yes | N24: =IF(I24=0,AVERAGE(G24,H24),MEDIAN(G24,H24,I24)) -> 7 | R24: =+B24 -> Calf sf | U24: =+N24 -> 7 | V24: mm | W24: =1/4.67*(+U24*((170.18/U$14)^1)-16) -> -2.0397775
B25: =IF(Info!D34,"Arm girth relaxed","PR Brazo relajado") -> Arm girth relaxed | G25: 37.5 | K25: =+(H25-G25)/(AVERAGE(G25:H25)) -> -1 | L25: =IF(ABS(K25)>1%,"Yes","No") -> Yes | N25: =IF(I25=0,AVERAGE(G25,H25),MEDIAN(G25,H25,I25)) -> 37.5 | R25: =+B25 -> Arm girth relaxed | U25: =+N25 -> 37.5 | V25: cm | W25: =1/2.33*(+U25*((170.18/U$14)^1)-26.89) -> 3.3448171
B26: =IF(Info!D34,"Corrected arm girth","PR Brazo corregido") -> Corrected arm girth | R26: =+B26 -> Corrected arm girth | U26: =+U25-(PI()*U17/10) -> 33.730089 | V26: cm | W26: =1/1.91*(+U26*((170.18/U$14)^1)-22.05) -> 4.7888303
B27: =IF(Info!D34,"Arm girth flexed and tensed","PR Brazo flexionado y contraído") -> Arm girth flexed and tensed | G27: 40.2 | K27: =+(H27-G27)/(AVERAGE(G27:H27)) -> -1 | L27: =IF(ABS(K27)>1%,"Yes","No") -> Yes | N27: =IF(I27=0,AVERAGE(G27,H27),MEDIAN(G27,H27,I27)) -> 40.2 | R27: =+B27 -> Arm girth flexed and tensed | U27: =+N27 -> 40.2 | V27: cm | W27: =1/2.37*(+U27*((170.18/U$14)^1)-29.41) -> 3.278747
B28: =IF(Info!D34,"Waist girth","PR Cintura") -> Waist girth | G28: 96 | K28: =+(H28-G28)/(AVERAGE(G28:H28)) -> -1 | L28: =IF(ABS(K28)>1%,"Yes","No") -> Yes | N28: =IF(I28=0,AVERAGE(G28,H28),MEDIAN(G28,H28,I28)) -> 96 | R28: =+B28 -> Waist girth | U28: =+N28 -> 96 | V28: cm | W28: =1/4.45*(+U28*((170.18/U$14)^1)-71.91) -> 3.7931607
B29: =IF(Info!D34,"Hips girth","PR Caderas") -> Hips girth | G29: 110 | K29: =+(H29-G29)/(AVERAGE(G29:H29)) -> -1 | L29: =IF(ABS(K29)>1%,"Yes","No") -> Yes | N29: =IF(I29=0,AVERAGE(G29,H29),MEDIAN(G29,H29,I29)) -> 110 | R29: =+B29 -> Hips girth | U29: =+N29 -> 110 | V29: cm | W29: =1/5.58*(+U29*((170.18/U$14)^1)-94.67) -> 1.2666745
B30: =IF(Info!D34,"Thigh middle girth","PR Muslo medio") -> Thigh middle girth | G30: 60.5 | K30: =+(H30-G30)/(AVERAGE(G30:H30)) -> -1 | L30: =IF(ABS(K30)>1%,"Yes","No") -> Yes | N30: =IF(I30=0,AVERAGE(G30,H30),MEDIAN(G30,H30,I30)) -> 60.5 | R30: =+B30 -> Thigh middle girth | U30: =+N30 -> 60.5 | V30: cm | W30: =1/4.56*(+U30*((170.18/U$14)^1)-53.2) -> 0.60436928
B31: =IF(Info!D34,"Corrected thigh girth","PR Muslo corregido") -> Corrected thigh girth | R31: =+B31 -> Corrected thigh girth | U31: =+U30-(PI()*U23/10) -> 53.588496 | V31: cm | W31: =1/3.59*(+U31*((170.18/U$14)^1)-47.34) -> 0.61936883
B32: =IF(Info!D34,"Calf girth","PR Pierna") -> Calf girth | G32: 41.2 | K32: =+(H32-G32)/(AVERAGE(G32:H32)) -> -1 | L32: =IF(ABS(K32)>1%,"Yes","No") -> Yes | N32: =IF(I32=0,AVERAGE(G32,H32),MEDIAN(G32,H32,I32)) -> 41.2 | R32: =+B32 -> Calf girth | U32: =+N32 -> 41.2 | V32: cm | W32: =1/2.3*(+U32*((170.18/U$14)^1)-35.25) -> 1.2415312
B33: =IF(Info!D34,"Corrected calf girth","PR Pierna corregido") -> Corrected calf girth | R33: =+B33 -> Corrected calf girth | U33: =+U32-(PI()*U24/10) -> 39.000885 | V33: cm | W33: =1/1.97*(+U33*((170.18/U$14)^1)-30.22) -> 2.9703449
B34: =IF(Info!D34,"Humerus breadth","D Húmero") -> Humerus breadth | G34: 7.2 | K34: =+(H34-G34)/(AVERAGE(G34:H34)) -> -1 | L34: =IF(ABS(K34)>1%,"Yes","No") -> Yes | N34: =IF(I34=0,AVERAGE(G34,H34),MEDIAN(G34,H34,I34)) -> 7.2 | R34: =+B34 -> Humerus breadth | U34: =+N34 -> 7.2 | V34: cm | W34: =1/0.35*(+U34*((170.18/U$14)^1)-6.48) -> 0.51204969
B35: =IF(Info!D34,"Bi-styloid breadth","D Biestiloideo") -> Bi-styloid breadth | G35: 5.8 | K35: =+(H35-G35)/(AVERAGE(G35:H35)) -> -1 | L35: =IF(ABS(K35)>1%,"Yes","No") -> Yes | N35: =IF(I35=0,AVERAGE(G35,H35),MEDIAN(G35,H35,I35)) -> 5.8 | R35: =+B35 -> Bi-styloid breadth | U35: =+N35 -> 5.8 | V35: cm | W35: =1/0.28*(+U35*((170.18/U$14)^1)-5.21) -> 0.55131988
B36: =IF(Info!D34,"Femur breadth","D Fémur") -> Femur breadth | G36: 10.8 | K36: =+(H36-G36)/(AVERAGE(G36:H36)) -> -1 | L36: =IF(ABS(K36)>1%,"Yes","No") -> Yes | N36: =IF(I36=0,AVERAGE(G36,H36),MEDIAN(G36,H36,I36)) -> 10.8 | R36: =+B36 -> Femur breadth | U36: =+N36 -> 10.8 | V36: cm | W36: =1/0.48*(+U36*((170.18/U$14)^1)-9.52) -> 0.97672101
D39: 1ª Vs 2ª | E39: 1ªVs 3ª | F39: 2ª Vs 3ª | G39: =IF(Info!D34,"3rd measure taken?","¿3ª medida tomada?") -> 3rd measure taken? | H39: =IF(Info!D34,"3rd measure requested?","¿3ª medida solicitada?") -> 3rd measure requested? | I39: =IF(Info!D34,"He/she has not done 1st measure","No se ha realizado la 1ª medición") -> He/she has not done 1st measure | J39: =IF(Info!E34,"He/she has not done 2nd measure","No se ha realizado la 2ª medición") -> No se ha realizado la 2ª medición
B40: =B13 -> Mass | D40: =IF(G13=H13,1,0) -> 0 | E40: =IF(G13=I13,1,0) -> 0 | F40: =IF(H13=I13,1,0) -> 1 | G40: =IF(I13="",0,1) -> 0 | H40: =IF(L13="Yes",1,0) -> 1 | I40: =COUNTIF(G13,"") -> 0 | J40: =COUNTIF(H13,"") -> 1 | S40: ='3'!S40 -> Somatotype | T40: =IF(Info!D34,"Endomorphy","Endomorfia") -> Endomorphy | U40: =-0.7182+0.1451*((U17+U18+U21)*(170.18/U14))-0.00068*(((U17+U18+U21)*(170.18/U14))^2)+0.0000014*(((U17+U18+U21)*(170.18/U14))^3) -> 4.4193307
B41: =B14 -> Stature | D41: =IF(G14=H14,1,0) -> 0 | E41: =IF(G14=I14,1,0) -> 0 | F41: =IF(H14=I14,1,0) -> 1 | G41: =IF(I14="",0,1) -> 0 | H41: =IF(L14="Yes",1,0) -> 1 | I41: =COUNTIF(G14,"") -> 0 | J41: =COUNTIF(H14,"") -> 1 | S41: ='3'!S41 -> (Heath-Carter) | T41: =IF(Info!D34,"Mesomorphy","Mesomorfia") -> Mesomorphy | U41: =(0.858*U34)+(0.601*U36)+(0.188*(U27-(U17/10)))+(0.161*(U32-(U24/10)))-(0.131*U14)+4.5 -> 6.9169
B42: =B15 -> Sitting height | D42: =IF(G15=H15,1,0) -> 1 | E42: =IF(G15=I15,1,0) -> 1 | F42: =IF(H15=I15,1,0) -> 1 | G42: =IF(I15="",0,1) -> 0 | H42: =IF(L15="Yes",1,0) -> #DIV/0! | I42: =COUNTIF(G15,"") -> 1 | J42: =COUNTIF(H15,"") -> 1 | T42: =IF(Info!D34,"Ectomorphy","Ectomorfia") -> Ectomorphy | U42: =IF(V42>40.75,((0.732*V42)-28.58),IF(V42>38.28,((0.463*V42)-17.63),0.1)) -> 0.87961031 | V42: =U14/(U13^(1/3)) -> 39.97756
B43: =B16 -> Arm Span | D43: =IF(G16=H16,1,0) -> 1 | E43: =IF(G16=I16,1,0) -> 1 | F43: =IF(H16=I16,1,0) -> 1 | G43: =IF(I16="",0,1) -> 0 | H43: =IF(L16="Yes",1,0) -> #DIV/0! | I43: =COUNTIF(G16,"") -> 1 | J43: =COUNTIF(H16,"") -> 1
B44: =B17 -> Triceps sf | D44: =IF(G17=H17,1,0) -> 0 | E44: =IF(G17=I17,1,0) -> 0 | F44: =IF(H17=I17,1,0) -> 1 | G44: =IF(I17="",0,1) -> 0 | H44: =IF(L17="Yes",1,0) -> 1 | I44: =COUNTIF(G17,"") -> 0 | J44: =COUNTIF(H17,"") -> 1 | S44: ='3'!S44 -> Body Mass Index (MBI) | U44: =+U13/(U14/100)^2 -> 28.79844 | V44: ='3'!V44 -> kg/m2
...

Sheet 3
B2: =IF(Info!D34,"ISAK RESTRICTED PROFORMA","PROFORMA PERFIL RESTRINGIDO ISAK") -> ISAK RESTRICTED PROFORMA | R2: =IF(Info!D34,"ISAK PROFORMA PRINTOUT","INFORME PROFORMA ISAK") -> ISAK PROFORMA PRINTOUT
B4: =IF(Info!D34,"Name","Nombre") -> Name | I4: ´+ | R4: =+B4 -> Name | U4: =+G4 -> 0
B5: =IF(Info!D34,"Surname","Apellidos") -> Surname | R5: =+B5 -> Surname | U5: =+G5 -> 0
B6: =IF(Info!D34,"Country","País") -> Country | R6: =+B6 -> Country | U6: =+G6 -> 0
B7: =IF(Info!D34,"Ethnicity (Asian=1; African-American=2; Caucasian=3)","Raza (asiático=1; afro-americano=2; caucásico=3)") -> Ethnicity (Asian=1; African-American=2; Caucasian=3) | R7: =+B7 -> Ethnicity (Asian=1; African-American=2; Caucasian=3) | U7: =+G7 -> 0
B8: =IF(Info!D34,"Sex (male=1, female=2)","Sexo (hombre=1, mujer=2)") -> Sex (male=1, female=2) | R8: =+B8 -> Sex (male=1, female=2) | U8: =+G8 -> 0
B9: =IF(Info!D34,"Sport","Deporte") -> Sport | R9: =+B9 -> Sport | U9: =+G9 -> 0
B10: =IF(Info!D34,"Date of Measurement","Fecha de la valoración") -> Date of Measurement | G10: 46189 | R10: =+B10 -> Date of Measurement | U10: =+G10 -> 46189
B11: =IF(Info!D34,"Date of Birth","Fecha de nacimiento") -> Date of Birth | K11: =IF(Info!D34,"3rd measure?","¿3ª medida?") -> 3rd measure? | N11: =IF(Info!D34,"Mean or Median","Media o Mediana") -> Mean or Median | R11: =+B11 -> Date of Birth | U11: =+G11 -> 0
B12: =IF(Info!D34,"Measure","Medida") -> Measure | G12: 1 | H12: 2 | I12: 3 | U12: =IF(Info!D34,"Value", "Valor") -> Value | W12: =IF(Info!D34,"Phantom Z-value","Valor Z del Phantom") -> Phantom Z-value
B13: =IF(Info!D34,"Mass","Masa corporal") -> Mass | G13: 99.4 | K13: =+(H13-G13)/(AVERAGE(G13:H13)) -> -1 | L13: =IF(ABS(K13)>1%,"Yes","No") -> Yes | N13: =IF(I13=0,AVERAGE(G13,H13),MEDIAN(G13,H13,I13)) -> 99.4 | R13: =+B13 -> Mass | U13: =+N13 -> 99.4 | V13: kg | W13: =1/8.6*(+U13*((170.18/U$14)^3)-64.58) -> #DIV/0!
B14: =IF(Info!D34,"Stature","Talla") -> Stature | K14: =+(H14-G14)/(AVERAGE(G14:H14)) -> #DIV/0! | L14: =IF(ABS(K14)>1%,"Yes","No") -> #DIV/0! | N14: =IF(I14=0,AVERAGE(G14,H14),MEDIAN(G14,H14,I14)) -> #DIV/0! | R14: =+B14 -> Stature | U14: =+N14 -> #DIV/0! | V14: cm
B15: =IF(Info!D34,"Sitting height","Talla sentado") -> Sitting height | K15: =+(H15-G15)/(AVERAGE(G15:H15)) -> #DIV/0! | L15: =IF(ABS(K15)>1%,"Yes","No") -> #DIV/0! | N15: =IF(I15=0,AVERAGE(G15,H15),MEDIAN(G15,H15,I15)) -> #DIV/0! | R15: =+B15 -> Sitting height | U15: =+N15 -> #DIV/0! | V15: cm | W15: =1/4.5*(+U15*((170.18/U$14)^1)-89.92) -> #DIV/0!
B16: =IF(Info!D34,"Arm Span","Envergadura de brazos") -> Arm Span | K16: =+(H16-G16)/(AVERAGE(G16:H16)) -> #DIV/0! | L16: =IF(ABS(K16)>1%,"Yes","No") -> #DIV/0! | N16: =IF(I16=0,AVERAGE(G16,H16),MEDIAN(G16,H16,I16)) -> #DIV/0! | R16: =+B16 -> Arm Span | U16: =+N16 -> #DIV/0! | V16: cm | W16: =1/7.41*(+U16*((170.18/U$14)^1)-172.35) -> #DIV/0!
B17: =IF(Info!D34,"Triceps sf","PL Tríceps") -> Triceps sf | G17: 12 | K17: =+(H17-G17)/(AVERAGE(G17:H17)) -> -1 | L17: =IF(ABS(K17)>5%,"Yes","No") -> Yes | N17: =IF(I17=0,AVERAGE(G17,H17),MEDIAN(G17,H17,I17)) -> 12 | R17: =+B17 -> Triceps sf | U17: =+N17 -> 12 | V17: mm | W17: =1/4.47*(+U17*((170.18/U$14)^1)-15.4) -> #DIV/0!
B18: =IF(Info!D34,"Subscapular sf","PL Subescapular") -> Subscapular sf | G18: 18 | K18: =+(H18-G18)/(AVERAGE(G18:H18)) -> -1 | L18: =IF(ABS(K18)>5%,"Yes","No") -> Yes | N18: =IF(I18=0,AVERAGE(G18,H18),MEDIAN(G18,H18,I18)) -> 18 | R18: =+B18 -> Subscapular sf | U18: =+N18 -> 18 | V18: mm | W18: =1/5.07*(+U18*((170.18/U$14)^1)-17.2) -> #DIV/0!
B19: =IF(Info!D34,"Biceps sf","PL Bíceps") -> Biceps sf | G19: 5 | K19: =+(H19-G19)/(AVERAGE(G19:H19)) -> -1 | L19: =IF(ABS(K19)>5%,"Yes","No") -> Yes | N19: =IF(I19=0,AVERAGE(G19,H19),MEDIAN(G19,H19,I19)) -> 5 | R19: =+B19 -> Biceps sf | U19: =+N19 -> 5 | V19: mm | W19: =1/2*(+U19*((170.18/U$14)^1)-8) -> #DIV/0!
B20: =IF(Info!D34,"Iliac crest sf","PL Cresta Iliaca") -> Iliac crest sf | G20: 35 | K20: =+(H20-G20)/(AVERAGE(G20:H20)) -> -1 | L20: =IF(ABS(K20)>5%,"Yes","No") -> Yes | N20: =IF(I20=0,AVERAGE(G20,H20),MEDIAN(G20,H20,I20)) -> 35 | R20: =+B20 -> Iliac crest sf | U20: =+N20 -> 35 | V20: mm | W20: =1/6.8*(+U20*((170.18/U$14)^1)-22.4) -> #DIV/0!
B21: =IF(Info!D34,"Supraspinale sf","PL Supraespinal") -> Supraspinale sf | G21: 16 | K21: =+(H21-G21)/(AVERAGE(G21:H21)) -> -1 | L21: =IF(ABS(K21)>5%,"Yes","No") -> Yes | N21: =IF(I21=0,AVERAGE(G21,H21),MEDIAN(G21,H21,I21)) -> 16 | R21: =+B21 -> Supraspinale sf | U21: =+N21 -> 16 | V21: mm | W21: =1/4.47*(+U21*((170.18/U$14)^1)-15.4) -> #DIV/0!
B22: =IF(Info!D34,"Abdominal sf","PL Abdominal") -> Abdominal sf | G22: 32 | K22: =+(H22-G22)/(AVERAGE(G22:H22)) -> -1 | L22: =IF(ABS(K22)>5%,"Yes","No") -> Yes | N22: =IF(I22=0,AVERAGE(G22,H22),MEDIAN(G22,H22,I22)) -> 32 | R22: =+B22 -> Abdominal sf | U22: =+N22 -> 32 | V22: mm | W22: =1/7.78*(+U22*((170.18/U$14)^1)-25.4) -> #DIV/0!
B23: =IF(Info!D34,"Thigh sf","PL Muslo") -> Thigh sf | G23: 22 | K23: =+(H23-G23)/(AVERAGE(G23:H23)) -> -1 | L23: =IF(ABS(K23)>5%,"Yes","No") -> Yes | N23: =IF(I23=0,AVERAGE(G23,H23),MEDIAN(G23,H23,I23)) -> 22 | R23: =+B23 -> Thigh sf | U23: =+N23 -> 22 | V23: mm | W23: =1/8.33*(+U23*((170.18/U$14)^1)-27) -> #DIV/0!
B24: =IF(Info!D34,"Calf sf","PL Pierna") -> Calf sf | G24: 7 | K24: =+(H24-G24)/(AVERAGE(G24:H24)) -> -1 | L24: =IF(ABS(K24)>5%,"Yes","No") -> Yes | N24: =IF(I24=0,AVERAGE(G24,H24),MEDIAN(G24,H24,I24)) -> 7 | R24: =+B24 -> Calf sf | U24: =+N24 -> 7 | V24: mm | W24: =1/4.67*(+U24*((170.18/U$14)^1)-16) -> #DIV/0!
B25: =IF(Info!D34,"Arm girth relaxed","PR Brazo relajado") -> Arm girth relaxed | G25: 37.4 | K25: =+(H25-G25)/(AVERAGE(G25:H25)) -> -1 | L25: =IF(ABS(K25)>1%,"Yes","No") -> Yes | N25: =IF(I25=0,AVERAGE(G25,H25),MEDIAN(G25,H25,I25)) -> 37.4 | R25: =+B25 -> Arm girth relaxed | U25: =+N25 -> 37.4 | V25: cm | W25: =1/2.33*(+U25*((170.18/U$14)^1)-26.89) -> #DIV/0!
B26: =IF(Info!D34,"Corrected arm girth","PR Brazo corregido") -> Corrected arm girth | R26: =+B26 -> Corrected arm girth | U26: =+U25-(PI()*U17/10) -> 33.630089 | V26: cm | W26: =1/1.91*(+U26*((170.18/U$14)^1)-22.05) -> #DIV/0!
B27: =IF(Info!D34,"Arm girth flexed and tensed","PR Brazo flexionado y contraído") -> Arm girth flexed and tensed | G27: 40 | K27: =+(H27-G27)/(AVERAGE(G27:H27)) -> -1 | L27: =IF(ABS(K27)>1%,"Yes","No") -> Yes | N27: =IF(I27=0,AVERAGE(G27,H27),MEDIAN(G27,H27,I27)) -> 40 | R27: =+B27 -> Arm girth flexed and tensed | U27: =+N27 -> 40 | V27: cm | W27: =1/2.37*(+U27*((170.18/U$14)^1)-29.41) -> #DIV/0!
B28: =IF(Info!D34,"Waist girth","PR Cintura") -> Waist girth | G28: 95 | K28: =+(H28-G28)/(AVERAGE(G28:H28)) -> -1 | L28: =IF(ABS(K28)>1%,"Yes","No") -> Yes | N28: =IF(I28=0,AVERAGE(G28,H28),MEDIAN(G28,H28,I28)) -> 95 | R28: =+B28 -> Waist girth | U28: =+N28 -> 95 | V28: cm | W28: =1/4.45*(+U28*((170.18/U$14)^1)-71.91) -> #DIV/0!
B29: =IF(Info!D34,"Hips girth","PR Caderas") -> Hips girth | G29: 109 | K29: =+(H29-G29)/(AVERAGE(G29:H29)) -> -1 | L29: =IF(ABS(K29)>1%,"Yes","No") -> Yes | N29: =IF(I29=0,AVERAGE(G29,H29),MEDIAN(G29,H29,I29)) -> 109 | R29: =+B29 -> Hips girth | U29: =+N29 -> 109 | V29: cm | W29: =1/5.58*(+U29*((170.18/U$14)^1)-94.67) -> #DIV/0!
B30: =IF(Info!D34,"Thigh middle girth","PR Muslo medio") -> Thigh middle girth | G30: 61 | K30: =+(H30-G30)/(AVERAGE(G30:H30)) -> -1 | L30: =IF(ABS(K30)>1%,"Yes","No") -> Yes | N30: =IF(I30=0,AVERAGE(G30,H30),MEDIAN(G30,H30,I30)) -> 61 | R30: =+B30 -> Thigh middle girth | U30: =+N30 -> 61 | V30: cm | W30: =1/4.56*(+U30*((170.18/U$14)^1)-53.2) -> #DIV/0!
B31: =IF(Info!D34,"Corrected thigh girth","PR Muslo corregido") -> Corrected thigh girth | R31: =+B31 -> Corrected thigh girth | U31: =+U30-(PI()*U23/10) -> 54.088496 | V31: cm | W31: =1/3.59*(+U31*((170.18/U$14)^1)-47.34) -> #DIV/0!
B32: =IF(Info!D34,"Calf girth","PR Pierna") -> Calf girth | G32: 41 | K32: =+(H32-G32)/(AVERAGE(G32:H32)) -> -1 | L32: =IF(ABS(K32)>1%,"Yes","No") -> Yes | N32: =IF(I32=0,AVERAGE(G32,H32),MEDIAN(G32,H32,I32)) -> 41 | R32: =+B32 -> Calf girth | U32: =+N32 -> 41 | V32: cm | W32: =1/2.3*(+U32*((170.18/U$14)^1)-35.25) -> #DIV/0!
B33: =IF(Info!D34,"Corrected calf girth","PR Pierna corregido") -> Corrected calf girth | R33: =+B33 -> Corrected calf girth | U33: =+U32-(PI()*U24/10) -> 38.800885 | V33: cm | W33: =1/1.97*(+U33*((170.18/U$14)^1)-30.22) -> #DIV/0!
B34: =IF(Info!D34,"Humerus breadth","D Húmero") -> Humerus breadth | K34: =+(H34-G34)/(AVERAGE(G34:H34)) -> #DIV/0! | L34: =IF(ABS(K34)>1%,"Yes","No") -> #DIV/0! | N34: =IF(I34=0,AVERAGE(G34,H34),MEDIAN(G34,H34,I34)) -> #DIV/0! | R34: =+B34 -> Humerus breadth | U34: =+N34 -> #DIV/0! | V34: cm | W34: =1/0.35*(+U34*((170.18/U$14)^1)-6.48) -> #DIV/0!
B35: =IF(Info!D34,"Bi-styloid breadth","D Biestiloideo") -> Bi-styloid breadth | K35: =+(H35-G35)/(AVERAGE(G35:H35)) -> #DIV/0! | L35: =IF(ABS(K35)>1%,"Yes","No") -> #DIV/0! | N35: =IF(I35=0,AVERAGE(G35,H35),MEDIAN(G35,H35,I35)) -> #DIV/0! | R35: =+B35 -> Bi-styloid breadth | U35: =+N35 -> #DIV/0! | V35: cm | W35: =1/0.28*(+U35*((170.18/U$14)^1)-5.21) -> #DIV/0!
B36: =IF(Info!D34,"Femur breadth","D Fémur") -> Femur breadth | K36: =+(H36-G36)/(AVERAGE(G36:H36)) -> #DIV/0! | L36: =IF(ABS(K36)>1%,"Yes","No") -> #DIV/0! | N36: =IF(I36=0,AVERAGE(G36,H36),MEDIAN(G36,H36,I36)) -> #DIV/0! | R36: =+B36 -> Femur breadth | U36: =+N36 -> #DIV/0! | V36: cm | W36: =1/0.48*(+U36*((170.18/U$14)^1)-9.52) -> #DIV/0!
D39: 1ª Vs 2ª | E39: 1ªVs 3ª | F39: 2ª Vs 3ª | G39: =IF(Info!D34,"3rd measure taken?","¿3ª medida tomada?") -> 3rd measure taken? | H39: =IF(Info!D34,"3rd measure requested?","¿3ª medida solicitada?") -> 3rd measure requested? | I39: =IF(Info!D34,"He/she has not done 1st measure","No se ha realizado la 1ª medición") -> He/she has not done 1st measure | J39: =IF(Info!E34,"He/she has not done 2nd measure","No se ha realizado la 2ª medición") -> No se ha realizado la 2ª medición
B40: =B13 -> Mass | D40: =IF(G13=H13,1,0) -> 0 | E40: =IF(G13=I13,1,0) -> 0 | F40: =IF(H13=I13,1,0) -> 1 | G40: =IF(I13="",0,1) -> 0 | H40: =IF(L13="Yes",1,0) -> 1 | I40: =COUNTIF(G13,"") -> 0 | J40: =COUNTIF(H13,"") -> 1 | S40: =IF(Info!D34,"Somatotype","Somatotipo") -> Somatotype | T40: =IF(Info!D34,"Endomorphy","Endomorfia") -> Endomorphy | U40: =-0.7182+0.1451*((U17+U18+U21)*(170.18/U14))-0.00068*(((U17+U18+U21)*(170.18/U14))^2)+0.0000014*(((U17+U18+U21)*(170.18/U14))^3) -> #DIV/0!
B41: =B14 -> Stature | D41: =IF(G14=H14,1,0) -> 1 | E41: =IF(G14=I14,1,0) -> 1 | F41: =IF(H14=I14,1,0) -> 1 | G41: =IF(I14="",0,1) -> 0 | H41: =IF(L14="Yes",1,0) -> #DIV/0! | I41: =COUNTIF(G14,"") -> 1 | J41: =COUNTIF(H14,"") -> 1 | S41: (Heath-Carter) | T41: =IF(Info!D34,"Mesomorphy","Mesomorfia") -> Mesomorphy | U41: =(0.858*U34)+(0.601*U36)+(0.188*(U27-(U17/10)))+(0.161*(U32-(U24/10)))-(0.131*U14)+4.5 -> #DIV/0!
B42: =B15 -> Sitting height | D42: =IF(G15=H15,1,0) -> 1 | E42: =IF(G15=I15,1,0) -> 1 | F42: =IF(H15=I15,1,0) -> 1 | G42: =IF(I15="",0,1) -> 0 | H42: =IF(L15="Yes",1,0) -> #DIV/0! | I42: =COUNTIF(G15,"") -> 1 | J42: =COUNTIF(H15,"") -> 1 | T42: =IF(Info!D34,"Ectomorphy","Ectomorfia") -> Ectomorphy | U42: =IF(V42>40.75,((0.732*V42)-28.58),IF(V42>38.28,((0.463*V42)-17.63),0.1)) -> #DIV/0! | V42: =U14/(U13^(1/3)) -> #DIV/0!
B43: =B16 -> Arm Span | D43: =IF(G16=H16,1,0) -> 1 | E43: =IF(G16=I16,1,0) -> 1 | F43: =IF(H16=I16,1,0) -> 1 | G43: =IF(I16="",0,1) -> 0 | H43: =IF(L16="Yes",1,0) -> #DIV/0! | I43: =COUNTIF(G16,"") -> 1 | J43: =COUNTIF(H16,"") -> 1
B44: =B17 -> Triceps sf | D44: =IF(G17=H17,1,0) -> 0 | E44: =IF(G17=I17,1,0) -> 0 | F44: =IF(H17=I17,1,0) -> 1 | G44: =IF(I17="",0,1) -> 0 | H44: =IF(L17="Yes",1,0) -> 1 | I44: =COUNTIF(G17,"") -> 0 | J44: =COUNTIF(H17,"") -> 1 | S44: =IF(Info!D34,"Body Mass Index (MBI)","Índice de Masa Corporal (IMC)" ) -> Body Mass Index (MBI) | U44: =+U13/(U14/100)^2 -> #DIV/0! | V44: kg/m2
...

Sheet 4
B2: =IF(Info!D34,"ISAK RESTRICTED PROFORMA","PROFORMA PERFIL RESTRINGIDO ISAK") -> ISAK RESTRICTED PROFORMA | R2: =IF(Info!D34,"ISAK PROFORMA PRINTOUT","INFORME PROFORMA ISAK") -> ISAK PROFORMA PRINTOUT
B4: =IF(Info!D34,"Name","Nombre") -> Name | R4: =+B4 -> Name | U4: =+G4 -> 0
B5: =IF(Info!D34,"Surname","Apellidos") -> Surname | R5: =+B5 -> Surname | U5: =+G5 -> 0
B6: =IF(Info!D34,"Country","País") -> Country | R6: =+B6 -> Country | U6: =+G6 -> 0
B7: =IF(Info!D34,"Ethnicity (Asian=1; African-American=2; Caucasian=3)","Raza (asiático=1; afro-americano=2; caucásico=3)") -> Ethnicity (Asian=1; African-American=2; Caucasian=3) | R7: =+B7 -> Ethnicity (Asian=1; African-American=2; Caucasian=3) | U7: =+G7 -> 0
B8: =IF(Info!D34,"Sex (male=1, female=2)","Sexo (hombre=1, mujer=2)") -> Sex (male=1, female=2) | R8: =+B8 -> Sex (male=1, female=2) | U8: =+G8 -> 0
B9: =IF(Info!D34,"Sport","Deporte") -> Sport | R9: =+B9 -> Sport | U9: =+G9 -> 0
B10: =IF(Info!D34,"Date of Measurement","Fecha de la valoración") -> Date of Measurement | R10: =+B10 -> Date of Measurement | U10: =+G10 -> 0
B11: =IF(Info!D34,"Date of Birth","Fecha de nacimiento") -> Date of Birth | K11: =IF(Info!D34,"3rd measure?","¿3ª medida?") -> 3rd measure? | N11: =IF(Info!D34,"Mean or Median","Media o Mediana") -> Mean or Median | R11: =+B11 -> Date of Birth | U11: =+G11 -> 0
B12: =IF(Info!D34,"Measure","Medida") -> Measure | G12: 1 | H12: 2 | I12: 3 | U12: =IF(Info!D34,"Value", "Valor") -> Value | W12: =IF(Info!D34,"Phantom Z-value","Valor Z del Phantom") -> Phantom Z-value
B13: =IF(Info!D34,"Mass","Masa corporal") -> Mass | K13: =+(H13-G13)/(AVERAGE(G13:H13)) -> #DIV/0! | L13: =IF(ABS(K13)>1%,"Yes","No") -> #DIV/0! | N13: =IF(I13=0,AVERAGE(G13,H13),MEDIAN(G13,H13,I13)) -> #DIV/0! | R13: =+B13 -> Mass | U13: =+N13 -> #DIV/0! | V13: kg | W13: =1/8.6*(+U13*((170.18/U$14)^3)-64.58) -> #DIV/0!
B14: =IF(Info!D34,"Stature","Talla") -> Stature | K14: =+(H14-G14)/(AVERAGE(G14:H14)) -> #DIV/0! | L14: =IF(ABS(K14)>1%,"Yes","No") -> #DIV/0! | N14: =IF(I14=0,AVERAGE(G14,H14),MEDIAN(G14,H14,I14)) -> #DIV/0! | R14: =+B14 -> Stature | U14: =+N14 -> #DIV/0! | V14: cm
B15: =IF(Info!D34,"Sitting height","Talla sentado") -> Sitting height | K15: =+(H15-G15)/(AVERAGE(G15:H15)) -> #DIV/0! | L15: =IF(ABS(K15)>1%,"Yes","No") -> #DIV/0! | N15: =IF(I15=0,AVERAGE(G15,H15),MEDIAN(G15,H15,I15)) -> #DIV/0! | R15: =+B15 -> Sitting height | U15: =+N15 -> #DIV/0! | V15: cm | W15: =1/4.5*(+U15*((170.18/U$14)^1)-89.92) -> #DIV/0!
B16: =IF(Info!D34,"Arm Span","Envergadura de brazos") -> Arm Span | K16: =+(H16-G16)/(AVERAGE(G16:H16)) -> #DIV/0! | L16: =IF(ABS(K16)>1%,"Yes","No") -> #DIV/0! | N16: =IF(I16=0,AVERAGE(G16,H16),MEDIAN(G16,H16,I16)) -> #DIV/0! | R16: =+B16 -> Arm Span | U16: =+N16 -> #DIV/0! | V16: cm | W16: =1/7.41*(+U16*((170.18/U$14)^1)-172.35) -> #DIV/0!
B17: =IF(Info!D34,"Triceps sf","PL Tríceps") -> Triceps sf | K17: =+(H17-G17)/(AVERAGE(G17:H17)) -> #DIV/0! | L17: =IF(ABS(K17)>5%,"Yes","No") -> #DIV/0! | N17: =IF(I17=0,AVERAGE(G17,H17),MEDIAN(G17,H17,I17)) -> #DIV/0! | R17: =+B17 -> Triceps sf | U17: =+N17 -> #DIV/0! | V17: mm | W17: =1/4.47*(+U17*((170.18/U$14)^1)-15.4) -> #DIV/0!
B18: =IF(Info!D34,"Subscapular sf","PL Subescapular") -> Subscapular sf | K18: =+(H18-G18)/(AVERAGE(G18:H18)) -> #DIV/0! | L18: =IF(ABS(K18)>5%,"Yes","No") -> #DIV/0! | N18: =IF(I18=0,AVERAGE(G18,H18),MEDIAN(G18,H18,I18)) -> #DIV/0! | R18: =+B18 -> Subscapular sf | U18: =+N18 -> #DIV/0! | V18: mm | W18: =1/5.07*(+U18*((170.18/U$14)^1)-17.2) -> #DIV/0!
B19: =IF(Info!D34,"Biceps sf","PL Bíceps") -> Biceps sf | K19: =+(H19-G19)/(AVERAGE(G19:H19)) -> #DIV/0! | L19: =IF(ABS(K19)>5%,"Yes","No") -> #DIV/0! | N19: =IF(I19=0,AVERAGE(G19,H19),MEDIAN(G19,H19,I19)) -> #DIV/0! | R19: =+B19 -> Biceps sf | U19: =+N19 -> #DIV/0! | V19: mm | W19: =1/2*(+U19*((170.18/U$14)^1)-8) -> #DIV/0!
B20: =IF(Info!D34,"Iliac crest sf","PL Cresta Iliaca") -> Iliac crest sf | K20: =+(H20-G20)/(AVERAGE(G20:H20)) -> #DIV/0! | L20: =IF(ABS(K20)>5%,"Yes","No") -> #DIV/0! | N20: =IF(I20=0,AVERAGE(G20,H20),MEDIAN(G20,H20,I20)) -> #DIV/0! | R20: =+B20 -> Iliac crest sf | U20: =+N20 -> #DIV/0! | V20: mm | W20: =1/6.8*(+U20*((170.18/U$14)^1)-22.4) -> #DIV/0!
B21: =IF(Info!D34,"Supraspinale sf","PL Supraespinal") -> Supraspinale sf | K21: =+(H21-G21)/(AVERAGE(G21:H21)) -> #DIV/0! | L21: =IF(ABS(K21)>5%,"Yes","No") -> #DIV/0! | N21: =IF(I21=0,AVERAGE(G21,H21),MEDIAN(G21,H21,I21)) -> #DIV/0! | R21: =+B21 -> Supraspinale sf | U21: =+N21 -> #DIV/0! | V21: mm | W21: =1/4.47*(+U21*((170.18/U$14)^1)-15.4) -> #DIV/0!
B22: =IF(Info!D34,"Abdominal sf","PL Abdominal") -> Abdominal sf | K22: =+(H22-G22)/(AVERAGE(G22:H22)) -> #DIV/0! | L22: =IF(ABS(K22)>5%,"Yes","No") -> #DIV/0! | N22: =IF(I22=0,AVERAGE(G22,H22),MEDIAN(G22,H22,I22)) -> #DIV/0! | R22: =+B22 -> Abdominal sf | U22: =+N22 -> #DIV/0! | V22: mm | W22: =1/7.78*(+U22*((170.18/U$14)^1)-25.4) -> #DIV/0!
B23: =IF(Info!D34,"Thigh sf","PL Muslo") -> Thigh sf | K23: =+(H23-G23)/(AVERAGE(G23:H23)) -> #DIV/0! | L23: =IF(ABS(K23)>5%,"Yes","No") -> #DIV/0! | N23: =IF(I23=0,AVERAGE(G23,H23),MEDIAN(G23,H23,I23)) -> #DIV/0! | R23: =+B23 -> Thigh sf | U23: =+N23 -> #DIV/0! | V23: mm | W23: =1/8.33*(+U23*((170.18/U$14)^1)-27) -> #DIV/0!
B24: =IF(Info!D34,"Calf sf","PL Pierna") -> Calf sf | K24: =+(H24-G24)/(AVERAGE(G24:H24)) -> #DIV/0! | L24: =IF(ABS(K24)>5%,"Yes","No") -> #DIV/0! | N24: =IF(I24=0,AVERAGE(G24,H24),MEDIAN(G24,H24,I24)) -> #DIV/0! | R24: =+B24 -> Calf sf | U24: =+N24 -> #DIV/0! | V24: mm | W24: =1/4.67*(+U24*((170.18/U$14)^1)-16) -> #DIV/0!
B25: =IF(Info!D34,"Arm girth relaxed","PR Brazo relajado") -> Arm girth relaxed | K25: =+(H25-G25)/(AVERAGE(G25:H25)) -> #DIV/0! | L25: =IF(ABS(K25)>1%,"Yes","No") -> #DIV/0! | N25: =IF(I25=0,AVERAGE(G25,H25),MEDIAN(G25,H25,I25)) -> #DIV/0! | R25: =+B25 -> Arm girth relaxed | U25: =+N25 -> #DIV/0! | V25: cm | W25: =1/2.33*(+U25*((170.18/U$14)^1)-26.89) -> #DIV/0!
B26: =IF(Info!D34,"Corrected arm girth","PR Brazo corregido") -> Corrected arm girth | R26: =+B26 -> Corrected arm girth | U26: =+U25-(PI()*U17/10) -> #DIV/0! | V26: cm | W26: =1/1.91*(+U26*((170.18/U$14)^1)-22.05) -> #DIV/0!
B27: =IF(Info!D34,"Arm girth flexed and tensed","PR Brazo flexionado y contraído") -> Arm girth flexed and tensed | K27: =+(H27-G27)/(AVERAGE(G27:H27)) -> #DIV/0! | L27: =IF(ABS(K27)>1%,"Yes","No") -> #DIV/0! | N27: =IF(I27=0,AVERAGE(G27,H27),MEDIAN(G27,H27,I27)) -> #DIV/0! | R27: =+B27 -> Arm girth flexed and tensed | U27: =+N27 -> #DIV/0! | V27: cm | W27: =1/2.37*(+U27*((170.18/U$14)^1)-29.41) -> #DIV/0!
B28: =IF(Info!D34,"Waist girth","PR Cintura") -> Waist girth | K28: =+(H28-G28)/(AVERAGE(G28:H28)) -> #DIV/0! | L28: =IF(ABS(K28)>1%,"Yes","No") -> #DIV/0! | N28: =IF(I28=0,AVERAGE(G28,H28),MEDIAN(G28,H28,I28)) -> #DIV/0! | R28: =+B28 -> Waist girth | U28: =+N28 -> #DIV/0! | V28: cm | W28: =1/4.45*(+U28*((170.18/U$14)^1)-71.91) -> #DIV/0!
B29: =IF(Info!D34,"Hips girth","PR Caderas") -> Hips girth | K29: =+(H29-G29)/(AVERAGE(G29:H29)) -> #DIV/0! | L29: =IF(ABS(K29)>1%,"Yes","No") -> #DIV/0! | N29: =IF(I29=0,AVERAGE(G29,H29),MEDIAN(G29,H29,I29)) -> #DIV/0! | R29: =+B29 -> Hips girth | U29: =+N29 -> #DIV/0! | V29: cm | W29: =1/5.58*(+U29*((170.18/U$14)^1)-94.67) -> #DIV/0!
B30: =IF(Info!D34,"Thigh middle girth","PR Muslo medio") -> Thigh middle girth | K30: =+(H30-G30)/(AVERAGE(G30:H30)) -> #DIV/0! | L30: =IF(ABS(K30)>1%,"Yes","No") -> #DIV/0! | N30: =IF(I30=0,AVERAGE(G30,H30),MEDIAN(G30,H30,I30)) -> #DIV/0! | R30: =+B30 -> Thigh middle girth | U30: =+N30 -> #DIV/0! | V30: cm | W30: =1/4.56*(+U30*((170.18/U$14)^1)-53.2) -> #DIV/0!
B31: =IF(Info!D34,"Corrected thigh girth","PR Muslo corregido") -> Corrected thigh girth | R31: =+B31 -> Corrected thigh girth | U31: =+U30-(PI()*U23/10) -> #DIV/0! | V31: cm | W31: =1/3.59*(+U31*((170.18/U$14)^1)-47.34) -> #DIV/0!
B32: =IF(Info!D34,"Calf girth","PR Pierna") -> Calf girth | K32: =+(H32-G32)/(AVERAGE(G32:H32)) -> #DIV/0! | L32: =IF(ABS(K32)>1%,"Yes","No") -> #DIV/0! | N32: =IF(I32=0,AVERAGE(G32,H32),MEDIAN(G32,H32,I32)) -> #DIV/0! | R32: =+B32 -> Calf girth | U32: =+N32 -> #DIV/0! | V32: cm | W32: =1/2.3*(+U32*((170.18/U$14)^1)-35.25) -> #DIV/0!
B33: =IF(Info!D34,"Corrected calf girth","PR Pierna corregido") -> Corrected calf girth | R33: =+B33 -> Corrected calf girth | U33: =+U32-(PI()*U24/10) -> #DIV/0! | V33: cm | W33: =1/1.97*(+U33*((170.18/U$14)^1)-30.22) -> #DIV/0!
B34: =IF(Info!D34,"Humerus breadth","D Húmero") -> Humerus breadth | K34: =+(H34-G34)/(AVERAGE(G34:H34)) -> #DIV/0! | L34: =IF(ABS(K34)>1%,"Yes","No") -> #DIV/0! | N34: =IF(I34=0,AVERAGE(G34,H34),MEDIAN(G34,H34,I34)) -> #DIV/0! | R34: =+B34 -> Humerus breadth | U34: =+N34 -> #DIV/0! | V34: cm | W34: =1/0.35*(+U34*((170.18/U$14)^1)-6.48) -> #DIV/0!
B35: =IF(Info!D34,"Bi-styloid breadth","D Biestiloideo") -> Bi-styloid breadth | K35: =+(H35-G35)/(AVERAGE(G35:H35)) -> #DIV/0! | L35: =IF(ABS(K35)>1%,"Yes","No") -> #DIV/0! | N35: =IF(I35=0,AVERAGE(G35,H35),MEDIAN(G35,H35,I35)) -> #DIV/0! | R35: =+B35 -> Bi-styloid breadth | U35: =+N35 -> #DIV/0! | V35: cm | W35: =1/0.28*(+U35*((170.18/U$14)^1)-5.21) -> #DIV/0!
B36: =IF(Info!D34,"Femur breadth","D Fémur") -> Femur breadth | K36: =+(H36-G36)/(AVERAGE(G36:H36)) -> #DIV/0! | L36: =IF(ABS(K36)>1%,"Yes","No") -> #DIV/0! | N36: =IF(I36=0,AVERAGE(G36,H36),MEDIAN(G36,H36,I36)) -> #DIV/0! | R36: =+B36 -> Femur breadth | U36: =+N36 -> #DIV/0! | V36: cm | W36: =1/0.48*(+U36*((170.18/U$14)^1)-9.52) -> #DIV/0!
D39: 1ª Vs 2ª | E39: 1ªVs 3ª | F39: 2ª Vs 3ª | G39: =IF(Info!D34,"3rd measure taken?","¿3ª medida tomada?") -> 3rd measure taken? | H39: =IF(Info!D34,"3rd measure requested?","¿3ª medida solicitada?") -> 3rd measure requested? | I39: =IF(Info!D34,"He/she has not done 1st measure","No se ha realizado la 1ª medición") -> He/she has not done 1st measure | J39: =IF(Info!E34,"He/she has not done 2nd measure","No se ha realizado la 2ª medición") -> No se ha realizado la 2ª medición
B40: =B13 -> Mass | D40: =IF(G13=H13,1,0) -> 1 | E40: =IF(G13=I13,1,0) -> 1 | F40: =IF(H13=I13,1,0) -> 1 | G40: =IF(I13="",0,1) -> 0 | H40: =IF(L13="Yes",1,0) -> #DIV/0! | I40: =COUNTIF(G13,"") -> 1 | J40: =COUNTIF(H13,"") -> 1 | S40: ='3'!S40 -> Somatotype | T40: =IF(Info!D34,"Endomorphy","Endomorfia") -> Endomorphy | U40: =-0.7182+0.1451*((U17+U18+U21)*(170.18/U14))-0.00068*(((U17+U18+U21)*(170.18/U14))^2)+0.0000014*(((U17+U18+U21)*(170.18/U14))^3) -> #DIV/0!
B41: =B14 -> Stature | D41: =IF(G14=H14,1,0) -> 1 | E41: =IF(G14=I14,1,0) -> 1 | F41: =IF(H14=I14,1,0) -> 1 | G41: =IF(I14="",0,1) -> 0 | H41: =IF(L14="Yes",1,0) -> #DIV/0! | I41: =COUNTIF(G14,"") -> 1 | J41: =COUNTIF(H14,"") -> 1 | S41: ='3'!S41 -> (Heath-Carter) | T41: =IF(Info!D34,"Mesomorphy","Mesomorfia") -> Mesomorphy | U41: =(0.858*U34)+(0.601*U36)+(0.188*(U27-(U17/10)))+(0.161*(U32-(U24/10)))-(0.131*U14)+4.5 -> #DIV/0!
B42: =B15 -> Sitting height | D42: =IF(G15=H15,1,0) -> 1 | E42: =IF(G15=I15,1,0) -> 1 | F42: =IF(H15=I15,1,0) -> 1 | G42: =IF(I15="",0,1) -> 0 | H42: =IF(L15="Yes",1,0) -> #DIV/0! | I42: =COUNTIF(G15,"") -> 1 | J42: =COUNTIF(H15,"") -> 1 | T42: =IF(Info!D34,"Ectomorphy","Ectomorfia") -> Ectomorphy | U42: =IF(V42>40.75,((0.732*V42)-28.58),IF(V42>38.28,((0.463*V42)-17.63),0.1)) -> #DIV/0! | V42: =U14/(U13^(1/3)) -> #DIV/0!
B43: =B16 -> Arm Span | D43: =IF(G16=H16,1,0) -> 1 | E43: =IF(G16=I16,1,0) -> 1 | F43: =IF(H16=I16,1,0) -> 1 | G43: =IF(I16="",0,1) -> 0 | H43: =IF(L16="Yes",1,0) -> #DIV/0! | I43: =COUNTIF(G16,"") -> 1 | J43: =COUNTIF(H16,"") -> 1
B44: =B17 -> Triceps sf | D44: =IF(G17=H17,1,0) -> 1 | E44: =IF(G17=I17,1,0) -> 1 | F44: =IF(H17=I17,1,0) -> 1 | G44: =IF(I17="",0,1) -> 0 | H44: =IF(L17="Yes",1,0) -> #DIV/0! | I44: =COUNTIF(G17,"") -> 1 | J44: =COUNTIF(H17,"") -> 1 | S44: ='3'!S44 -> Body Mass Index (MBI) | U44: =+U13/(U14/100)^2 -> #DIV/0! | V44: ='3'!V44 -> kg/m2
...

Sheet 5
B2: =IF(Info!D34,"ISAK RESTRICTED PROFORMA","PROFORMA PERFIL RESTRINGIDO ISAK") -> ISAK RESTRICTED PROFORMA | R2: =IF(Info!D34,"ISAK PROFORMA PRINTOUT","INFORME PROFORMA ISAK") -> ISAK PROFORMA PRINTOUT
B4: =IF(Info!D34,"Name","Nombre") -> Name | R4: =+B4 -> Name | U4: =+G4 -> 0
B5: =IF(Info!D34,"Surname","Apellidos") -> Surname | R5: =+B5 -> Surname | U5: =+G5 -> 0
B6: =IF(Info!D34,"Country","País") -> Country | R6: =+B6 -> Country | U6: =+G6 -> 0
B7: =IF(Info!D34,"Ethnicity (Asian=1; African-American=2; Caucasian=3)","Raza (asiático=1; afro-americano=2; caucásico=3)") -> Ethnicity (Asian=1; African-American=2; Caucasian=3) | R7: =+B7 -> Ethnicity (Asian=1; African-American=2; Caucasian=3) | U7: =+G7 -> 0
B8: =IF(Info!D34,"Sex (male=1, female=2)","Sexo (hombre=1, mujer=2)") -> Sex (male=1, female=2) | R8: =+B8 -> Sex (male=1, female=2) | U8: =+G8 -> 0
B9: =IF(Info!D34,"Sport","Deporte") -> Sport | R9: =+B9 -> Sport | U9: =+G9 -> 0
B10: =IF(Info!D34,"Date of Measurement","Fecha de la valoración") -> Date of Measurement | R10: =+B10 -> Date of Measurement | U10: =+G10 -> 0
B11: =IF(Info!D34,"Date of Birth","Fecha de nacimiento") -> Date of Birth | K11: =IF(Info!D34,"3rd measure?","¿3ª medida?") -> 3rd measure? | N11: =IF(Info!D34,"Mean or Median","Media o Mediana") -> Mean or Median | R11: =+B11 -> Date of Birth | U11: =+G11 -> 0
B12: =IF(Info!D34,"Measure","Medida") -> Measure | G12: 1 | H12: 2 | I12: 3 | U12: =IF(Info!D34,"Value", "Valor") -> Value | W12: =IF(Info!D34,"Phantom Z-value","Valor Z del Phantom") -> Phantom Z-value
B13: =IF(Info!D34,"Mass","Masa corporal") -> Mass | K13: =+(H13-G13)/(AVERAGE(G13:H13)) -> #DIV/0! | L13: =IF(ABS(K13)>1%,"Yes","No") -> #DIV/0! | N13: =IF(I13=0,AVERAGE(G13,H13),MEDIAN(G13,H13,I13)) -> #DIV/0! | R13: =+B13 -> Mass | U13: =+N13 -> #DIV/0! | V13: kg | W13: =1/8.6*(+U13*((170.18/U$14)^3)-64.58) -> #DIV/0!
B14: =IF(Info!D34,"Stature","Talla") -> Stature | K14: =+(H14-G14)/(AVERAGE(G14:H14)) -> #DIV/0! | L14: =IF(ABS(K14)>1%,"Yes","No") -> #DIV/0! | N14: =IF(I14=0,AVERAGE(G14,H14),MEDIAN(G14,H14,I14)) -> #DIV/0! | R14: =+B14 -> Stature | U14: =+N14 -> #DIV/0! | V14: cm
B15: =IF(Info!D34,"Sitting height","Talla sentado") -> Sitting height | K15: =+(H15-G15)/(AVERAGE(G15:H15)) -> #DIV/0! | L15: =IF(ABS(K15)>1%,"Yes","No") -> #DIV/0! | N15: =IF(I15=0,AVERAGE(G15,H15),MEDIAN(G15,H15,I15)) -> #DIV/0! | R15: =+B15 -> Sitting height | U15: =+N15 -> #DIV/0! | V15: cm | W15: =1/4.5*(+U15*((170.18/U$14)^1)-89.92) -> #DIV/0!
B16: =IF(Info!D34,"Arm Span","Envergadura de brazos") -> Arm Span | K16: =+(H16-G16)/(AVERAGE(G16:H16)) -> #DIV/0! | L16: =IF(ABS(K16)>1%,"Yes","No") -> #DIV/0! | N16: =IF(I16=0,AVERAGE(G16,H16),MEDIAN(G16,H16,I16)) -> #DIV/0! | R16: =+B16 -> Arm Span | U16: =+N16 -> #DIV/0! | V16: cm | W16: =1/7.41*(+U16*((170.18/U$14)^1)-172.35) -> #DIV/0!
B17: =IF(Info!D34,"Triceps sf","PL Tríceps") -> Triceps sf | K17: =+(H17-G17)/(AVERAGE(G17:H17)) -> #DIV/0! | L17: =IF(ABS(K17)>5%,"Yes","No") -> #DIV/0! | N17: =IF(I17=0,AVERAGE(G17,H17),MEDIAN(G17,H17,I17)) -> #DIV/0! | R17: =+B17 -> Triceps sf | U17: =+N17 -> #DIV/0! | V17: mm | W17: =1/4.47*(+U17*((170.18/U$14)^1)-15.4) -> #DIV/0!
B18: =IF(Info!D34,"Subscapular sf","PL Subescapular") -> Subscapular sf | K18: =+(H18-G18)/(AVERAGE(G18:H18)) -> #DIV/0! | L18: =IF(ABS(K18)>5%,"Yes","No") -> #DIV/0! | N18: =IF(I18=0,AVERAGE(G18,H18),MEDIAN(G18,H18,I18)) -> #DIV/0! | R18: =+B18 -> Subscapular sf | U18: =+N18 -> #DIV/0! | V18: mm | W18: =1/5.07*(+U18*((170.18/U$14)^1)-17.2) -> #DIV/0!
B19: =IF(Info!D34,"Biceps sf","PL Bíceps") -> Biceps sf | K19: =+(H19-G19)/(AVERAGE(G19:H19)) -> #DIV/0! | L19: =IF(ABS(K19)>5%,"Yes","No") -> #DIV/0! | N19: =IF(I19=0,AVERAGE(G19,H19),MEDIAN(G19,H19,I19)) -> #DIV/0! | R19: =+B19 -> Biceps sf | U19: =+N19 -> #DIV/0! | V19: mm | W19: =1/2*(+U19*((170.18/U$14)^1)-8) -> #DIV/0!
B20: =IF(Info!D34,"Iliac crest sf","PL Cresta Iliaca") -> Iliac crest sf | K20: =+(H20-G20)/(AVERAGE(G20:H20)) -> #DIV/0! | L20: =IF(ABS(K20)>5%,"Yes","No") -> #DIV/0! | N20: =IF(I20=0,AVERAGE(G20,H20),MEDIAN(G20,H20,I20)) -> #DIV/0! | R20: =+B20 -> Iliac crest sf | U20: =+N20 -> #DIV/0! | V20: mm | W20: =1/6.8*(+U20*((170.18/U$14)^1)-22.4) -> #DIV/0!
B21: =IF(Info!D34,"Supraspinale sf","PL Supraespinal") -> Supraspinale sf | K21: =+(H21-G21)/(AVERAGE(G21:H21)) -> #DIV/0! | L21: =IF(ABS(K21)>5%,"Yes","No") -> #DIV/0! | N21: =IF(I21=0,AVERAGE(G21,H21),MEDIAN(G21,H21,I21)) -> #DIV/0! | R21: =+B21 -> Supraspinale sf | U21: =+N21 -> #DIV/0! | V21: mm | W21: =1/4.47*(+U21*((170.18/U$14)^1)-15.4) -> #DIV/0!
B22: =IF(Info!D34,"Abdominal sf","PL Abdominal") -> Abdominal sf | K22: =+(H22-G22)/(AVERAGE(G22:H22)) -> #DIV/0! | L22: =IF(ABS(K22)>5%,"Yes","No") -> #DIV/0! | N22: =IF(I22=0,AVERAGE(G22,H22),MEDIAN(G22,H22,I22)) -> #DIV/0! | R22: =+B22 -> Abdominal sf | U22: =+N22 -> #DIV/0! | V22: mm | W22: =1/7.78*(+U22*((170.18/U$14)^1)-25.4) -> #DIV/0!
B23: =IF(Info!D34,"Thigh sf","PL Muslo") -> Thigh sf | K23: =+(H23-G23)/(AVERAGE(G23:H23)) -> #DIV/0! | L23: =IF(ABS(K23)>5%,"Yes","No") -> #DIV/0! | N23: =IF(I23=0,AVERAGE(G23,H23),MEDIAN(G23,H23,I23)) -> #DIV/0! | R23: =+B23 -> Thigh sf | U23: =+N23 -> #DIV/0! | V23: mm | W23: =1/8.33*(+U23*((170.18/U$14)^1)-27) -> #DIV/0!
B24: =IF(Info!D34,"Calf sf","PL Pierna") -> Calf sf | K24: =+(H24-G24)/(AVERAGE(G24:H24)) -> #DIV/0! | L24: =IF(ABS(K24)>5%,"Yes","No") -> #DIV/0! | N24: =IF(I24=0,AVERAGE(G24,H24),MEDIAN(G24,H24,I24)) -> #DIV/0! | R24: =+B24 -> Calf sf | U24: =+N24 -> #DIV/0! | V24: mm | W24: =1/4.67*(+U24*((170.18/U$14)^1)-16) -> #DIV/0!
B25: =IF(Info!D34,"Arm girth relaxed","PR Brazo relajado") -> Arm girth relaxed | K25: =+(H25-G25)/(AVERAGE(G25:H25)) -> #DIV/0! | L25: =IF(ABS(K25)>1%,"Yes","No") -> #DIV/0! | N25: =IF(I25=0,AVERAGE(G25,H25),MEDIAN(G25,H25,I25)) -> #DIV/0! | R25: =+B25 -> Arm girth relaxed | U25: =+N25 -> #DIV/0! | V25: cm | W25: =1/2.33*(+U25*((170.18/U$14)^1)-26.89) -> #DIV/0!
B26: =IF(Info!D34,"Corrected arm girth","PR Brazo corregido") -> Corrected arm girth | R26: =+B26 -> Corrected arm girth | U26: =+U25-(PI()*U17/10) -> #DIV/0! | V26: cm | W26: =1/1.91*(+U26*((170.18/U$14)^1)-22.05) -> #DIV/0!
